Workbook

Sheet Cashflows
B1: Cashflows
B4: Entradas de caja | C4: 43101 | D4: 43132 | E4: 43160 | F4: 43191 | G4: 43221 | H4: 43252 | I4: 43282 | J4: 43313 | K4: 43344 | L4: 43374 | M4: 43405 | N4: 43435
B5: Capital inicial | C5: 3000
B6: Dinero en mano principio mes | D6: =C53 -> 3000 | E6: =D53 -> 3000 | F6: =E53 -> 3000 | G6: =F53 -> 3000 | H6: =G53 -> 3000 | I6: =H53 -> 3000 | J6: =I53 -> 3000 | K6: =J53 -> 3000 | ... N6: =M53 -> 3000
B7: Ventas
B8: Ingresos financieros
B9: Otros Ingresos
B10: TOTAL ENTRADAS | C10: =SUM(C7:C9) -> 0 | D10: =SUM(D7:D9) -> 0 | E10: =SUM(E7:E9) -> 0 | F10: =SUM(F7:F9) -> 0 | G10: =SUM(G7:G9) -> 0 | H10: =SUM(H7:H9) -> 0 | I10: =SUM(I7:I9) -> 0 | J10: =SUM(J7:J9) -> 0 | ... N10: =SUM(N7:N9) -> 0
B14: Salidas de caja | C14: 43101 | D14: 43132 | E14: 43160 | F14: 43191 | G14: 43221 | H14: 43252 | I14: 43282 | J14: 43313 | K14: 43344 | L14: 43374 | M14: 43405 | N14: 43435
B15: TOTAL COMPRAS EXISTENCIAS | C15: =SUM(C16:C19) -> 0 | D15: =SUM(D16:D19) -> 0 | E15: =SUM(E16:E19) -> 0 | F15: =SUM(F16:F19) -> 0 | G15: =SUM(G16:G19) -> 0 | H15: =SUM(H16:H19) -> 0 | I15: =SUM(I16:I19) -> 0 | J15: =SUM(J16:J19) -> 0 | ... N15: =SUM(N16:N19) -> 0
B16: Producto terminado A
B17: Producto terminado b
B18: Producto semiterminado B
B19: Packaging
B20: TOTAL SERVICIOS ONLINE | C20: =SUM(C21:C23) -> 0 | D20: =SUM(D21:D23) -> 0 | E20: =SUM(E21:E23) -> 0 | F20: =SUM(F21:F23) -> 0 | G20: =SUM(G21:G23) -> 0 | H20: =SUM(H21:H23) -> 0 | I20: =SUM(I21:I23) -> 0 | J20: =SUM(J21:J23) -> 0 | ... N20: =SUM(N21:N23) -> 0
B21: Ecommerce
B22: Correos
B23: Cloud Services
B24: TOTAL MARKETING | C24: =SUM(C25:C29) -> 0 | D24: =SUM(D25:D29) -> 0 | E24: =SUM(E25:E29) -> 0 | F24: =SUM(F25:F29) -> 0 | G24: =SUM(G25:G29) -> 0 | H24: =SUM(H25:H29) -> 0 | I24: =SUM(I25:I29) -> 0 | J24: =SUM(J25:J29) -> 0 | ... N24: =SUM(N25:N29) -> 0
B25: Facebook Ads
B26: Instagram Ads
B27: Google Ads
B28: Youtube Ads
B29: Email Marketing
B30: TOTAL SUELDOS Y SALARIOS | C30: =SUM(C31:C33) -> 0 | D30: =SUM(D31:D33) -> 0 | E30: =SUM(E31:E33) -> 0 | F30: =SUM(F31:F33) -> 0 | G30: =SUM(G31:G33) -> 0 | H30: =SUM(H31:H33) -> 0 | I30: =SUM(I31:I33) -> 0 | J30: =SUM(J31:J33) -> 0 | ... N30: =SUM(N31:N33) -> 0
B31: Salario X
B32: Salario Y
B33: Salario Z
B34: TOTAL INMOVILIZADO | C34: =SUM(C35:C40) -> 0 | D34: =SUM(D35:D40) -> 0 | E34: =SUM(E35:E40) -> 0 | F34: =SUM(F35:F40) -> 0 | G34: =SUM(G35:G40) -> 0 | H34: =SUM(H35:H40) -> 0 | I34: =SUM(I35:I40) -> 0 | J34: =SUM(J35:J40) -> 0 | ... N34: =SUM(N35:N40) -> 0
B35: Alquiler oficina
B36: Seguro
B37: Alarma
B38: Fianzas
B39: Suministros
B40: Otros
B41: TOTAL LEGAL Y FINANCIERO | C41: =SUM(C42:C45) -> 0 | D41: =SUM(D42:D45) -> 0 | E41: =SUM(E42:E45) -> 0 | F41: =SUM(F42:F45) -> 0 | G41: =SUM(G42:G45) -> 0 | H41: =SUM(H42:H45) -> 0 | I41: =SUM(I42:I45) -> 0 | J41: =SUM(J42:J45) -> 0 | ... N41: =SUM(N42:N45) -> 0
B42: Gestoría
B43: Abogados
B44: Comisiones bancarias
B45: Otros gastos financieros
...

Sheet PyG
B1: Pérdidas y Ganancias (P&L)
C3: 2018 | D3: 2019 | E3: 2020 | F3: 2021 | G3: 2022 | H3: 2023 | I3: 2024 | J3: 2025 | K3: 2026 | L3: 2027 | M3: 2028 | N3: 2029 | O3: 2030
B4: (+) Ventas
B5: (-) Coste de las ventas (COGS)
B6: (=) Margen Burto | C6: =C4-C5 -> 0 | D6: =D4-D5 -> 0 | E6: =E4-E5 -> 0 | F6: =F4-F5 -> 0 | G6: =G4-G5 -> 0 | H6: =H4-H5 -> 0 | I6: =I4-I5 -> 0 | J6: =J4-J5 -> 0 | ... O6: =O4-O5 -> 0
B7: (-) Gastos Administrativos
B8: (-) Sueldos y salarios
B9: (=) Beneficio antes de intereses, impuestos, depreciaciones y amortizaciones (EBITDA) | C9: =C6-C7-C8 -> 0 | D9: =D6-D7-D8 -> 0 | E9: =E6-E7-E8 -> 0 | F9: =F6-F7-F8 -> 0 | G9: =G6-G7-G8 -> 0 | H9: =H6-H7-H8 -> 0 | I9: =I6-I7-I8 -> 0 | J9: =J6-J7-J8 -> 0 | ... O9: =O6-O7-O8 -> 0
B10: (-) Amortizaciones
B11: (-) Provisiones
B12: (=) Beneficio antes de intereses e impuestos (EBIT) | C12: =C9-C10-C11 -> 0 | D12: =D9-D10-D11 -> 0 | E12: =E9-E10-E11 -> 0 | F12: =F9-F10-F11 -> 0 | G12: =G9-G10-G11 -> 0 | H12: =H9-H10-H11 -> 0 | I12: =I9-I10-I11 -> 0 | J12: =J9-J10-J11 -> 0 | ... O12: =O9-O10-O11 -> 0
B13: (+) Ingresos extraordinarios
B14: (-) Gastos extraordinarios
B15: (=) Resultado ordinario | C15: =C12+C13-C14 -> 0 | D15: =D12+D13-D14 -> 0 | E15: =E12+E13-E14 -> 0 | F15: =F12+F13-F14 -> 0 | G15: =G12+G13-G14 -> 0 | H15: =H12+H13-H14 -> 0 | I15: =I12+I13-I14 -> 0 | J15: =J12+J13-J14 -> 0 | ... O15: =O12+O13-O14 -> 0
B16: (+)Ingresos Financieros
B17: (-) Gastos Financieros
B18: (=) Beneficio antes de Impuestos (EBT) | C18: =C15+C16-C17 -> 0 | D18: =D15+D16-D17 -> 0 | E18: =E15+E16-E17 -> 0 | F18: =F15+F16-F17 -> 0 | G18: =G15+G16-G17 -> 0 | H18: =H15+H16-H17 -> 0 | I18: =I15+I16-I17 -> 0 | J18: =J15+J16-J17 -> 0 | ... O18: =O15+O16-O17 -> 0
B19: (-) Impuesto de Sociedades
B20: (=) Beneficio neto o Resultado del Ejercicio | C20: =C18-C19 -> 0 | D20: =D18-D19 -> 0 | E20: =E18-E19 -> 0 | F20: =F18-F19 -> 0 | G20: =G18-G19 -> 0 | H20: =H18-H19 -> 0 | I20: =I18-I19 -> 0 | J20: =J18-J19 -> 0 | ... O20: =O18-O19 -> 0
B23: Ratios
C24: 2018 | D24: 2019 | E24: 2020 | F24: 2021 | G24: 2022 | H24: 2023 | I24: 2024 | J24: 2025 | K24: 2026 | L24: 2027 | M24: 2028 | N24: 2029 | O24: 2030
B25: Crecimiento de las ventas | D25: =(D4-C4)/C4 -> #DIV/0! | E25: =(E4-D4)/D4 -> #DIV/0! | F25: =(F4-E4)/E4 -> #DIV/0! | G25: =(G4-F4)/F4 -> #DIV/0! | H25: =(H4-G4)/G4 -> #DIV/0! | I25: =(I4-H4)/H4 -> #DIV/0! | J25: =(J4-I4)/I4 -> #DIV/0! | K25: =(K4-J4)/J4 -> #DIV/0! | ... O25: =(O4-N4)/N4 -> #DIV/0!
B26: Margen / Ventas | C26: =C6/C4 -> #DIV/0! | D26: =D6/D4 -> #DIV/0! | E26: =E6/E4 -> #DIV/0! | F26: =F6/F4 -> #DIV/0! | G26: =G6/G4 -> #DIV/0! | H26: =H6/H4 -> #DIV/0! | I26: =I6/I4 -> #DIV/0! | J26: =J6/J4 -> #DIV/0! | ... O26: =O6/O4 -> #DIV/0!
B27: Return on Sales (ROS): Beneficio neto / Ventas | C27: =C20/C4 -> #DIV/0! | D27: =D20/D4 -> #DIV/0! | E27: =E20/E4 -> #DIV/0! | F27: =F20/F4 -> #DIV/0! | G27: =G20/G4 -> #DIV/0! | H27: =H20/H4 -> #DIV/0! | I27: =I20/I4 -> #DIV/0! | J27: =J20/J4 -> #DIV/0! | ... O27: =O20/O4 -> #DIV/0!
B28: Return on Equity (ROE): Beneficio neto / Fondos Propios | C28: =C20/Balances!E6 -> #REF! | D28: =D20/Balances!J6 -> #REF! | E28: =E20/Balances!E51 -> #REF! | F28: =F20/Balances!J51 -> #REF! | G28: =G20/Balances!E96 -> #REF! | H28: =H20/Balances!J96 -> #REF! | I28: =I20/Balances!E141 -> #REF! | J28: =J20/Balances!J141 -> #REF! | K28: =K20/Balances!E186 -> #REF! | L28: =L20/Balances!J186 -> #REF! | M28: =M20/Balances!E231 -> #REF! | N28: =N20/Balances!J231 -> #REF! | O28: =O20/Balances!E276 -> #REF!
B29: Return on Assets (ROA): EBIT / Activos totales | C29: =C12/Balances!C44 -> #REF! | D29: =D12/Balances!H44 -> #REF! | E29: =E12/Balances!C89 -> #REF! | F29: =F12/Balances!H89 -> #REF! | G29: =G12/Balances!C134 -> #REF! | H29: =H12/Balances!H134 -> #REF! | I29: =I12/Balances!C179 -> #REF! | J29: =J12/Balances!H179 -> #REF! | K29: =K12/Balances!C224 -> #REF! | L29: =L12/Balances!H224 -> #REF! | M29: =M12/Balances!C269 -> #REF! | N29: =N12/Balances!H269 -> #REF! | O29: =O12/Balances!C314 -> #REF!
